<?xml version="1.0"?>
<sdf version="1.0">
  <model name="SIM_IKART">
    <static>false</static>
    <link name="mobile_base_body">
      <pose> 0 0 .181 0 0 0 </pose>
      <inertial>
        <mass>75</mass>
      </inertial>
      <collision name="mobile_base_body_collision">
        <geometry>
          <cylinder>
            <radius> .3575 </radius>
            <length> .237 </length>
          </cylinder>
        </geometry>
      </collision>
      <visual name="mobile_base_body_visual">
        <geometry>
          <cylinder>
            <radius> .3575 </radius>
            <length> .237 </length>
          </cylinder>
        </geometry>
      </visual>
      <!-- <collision name = 'caster_radar_collision'>
	<pose> 0.25 0 -0.1625 0 0 0 </pose>
	<geometry>
	  <sphere>
	    <radius> .0625 </radius>
	  </sphere>
	</geometry>

	<surface>
	  <friction>
	    <ode>
	      <mu>0</mu>
	      <mu2>0</mu2>
	    </ode>
	  </friction>
	</surface>
      </collision>-->
      <!-- <visual name = 'caster_radar_visual'>
	<pose> .25 0 -0.1625 0 0 0 </pose>
	<geometry>
	  <sphere>
	    <radius> .0625 </radius>
	  </sphere>
	</geometry>
      </visual>-->
      <!--  <collision name = 'caster_radar_back_right_collision'>
	<pose> -0.20 -0.20 -0.1625 0 0 0 </pose>
	<geometry>
	  <sphere>
	    <radius> .0625 </radius>
	  </sphere>
	</geometry>

	<surface>
	  <friction>
	    <ode>
	      <mu>0</mu>
	      <mu2>0</mu2>
	    </ode>
	  </friction>
	</surface>
      </collision>-->
      <!--   <visual name = 'caster_radar_back_right_visual'>
	<pose> -0.20 -0.20 -0.1625 0 0 0 </pose>
	<geometry>
	  <sphere>
	    <radius> .0625 </radius>
	  </sphere>
	</geometry>
      </visual>-->
      <!--   <collision name = 'caster_radar_back_left_collision'>
	<pose> -0.20 0.20 -0.1625 0 0 0 </pose>
	<geometry>
	  <sphere>
	    <radius> .0625 </radius>
	  </sphere>
	</geometry>

	<surface>
	  <friction>
	    <ode>
	      <mu>0</mu>
	      <mu2>0</mu2>
	    </ode>
	  </friction>
	</surface>
      </collision>-->
      <!--    <visual name = 'caster_radar_back_left_visual'>
	<pose> -0.20 0.20 -0.1625 0 0 0 </pose>
	<geometry>
	  <sphere>
	    <radius> .0625 </radius>
	  </sphere>
	</geometry>
      </visual>-->
      <visual name="laser_box_body_visual">
        <pose> .245 0 .15 0 0 0</pose>
        <geometry>
          <box>
            <size> .056 .056 .0495 </size>
          </box>
        </geometry>
      </visual>
      <sensor name="base_laser" type="ray">
        <pose> .245 0 .15 0 0 0</pose>
        <visualize>true</visualize>
        <update_rate>40</update_rate>
        <ray>
          <scan>
            <horizontal>
              <samples>1080</samples>
              <resolution>0.25</resolution>
              <min_angle>-2.35</min_angle>
              <max_angle>2.35</max_angle>
            </horizontal>
          </scan>
          <range>
            <min>0.1</min>
            <max>30</max>
            <resolution>.01</resolution>
          </range>
          <noise>
            <type>gaussian</type>
            <mean>.0</mean>
            <stddev>.005</stddev>
          </noise>
        </ray>
        <plugin name="laser_sensor" filename="libgazebo_yarp_lasersensor.so">
          <yarpConfigurationFile>model://ikart_v1/conf/gazebo_ikart_laser_sensor.ini</yarpConfigurationFile>
        </plugin>
      </sensor>
    </link>
    <link name="laser_back_wheel">
      <pose> -0.273 0 0.0625 0 -1.5707 0 </pose>
      <collision name="laser_back_wheel_collision">
        <geometry>
          <cylinder>
            <radius> .0625 </radius>
            <length> .025 </length>
          </cylinder>
        </geometry>
        <surface>
          <friction>
            <ode>
              <mu>0.3</mu>
              <mu2>0</mu2>
            </ode>
          </friction>
        </surface>
      </collision>
      <visual name="laser_back_wheel_visual">
        <geometry>
          <cylinder>
            <radius> .0625 </radius>
            <length> .025 </length>
          </cylinder>
        </geometry>
      </visual>
    </link>
    <link name="laser_front_left_wheel">
      <pose> 0.1365 0.2364 0.0625 0 1.5707 0.8666 </pose>
      <collision name="laser_front_left_wheel_collision">
        <geometry>
          <cylinder>
            <radius> .0625 </radius>
            <length> .025 </length>
          </cylinder>
        </geometry>
        <surface>
          <friction>
            <ode>
              <mu>0.3</mu>
              <mu2>0</mu2>
            </ode>
          </friction>
        </surface>
      </collision>
      <visual name="laser_front_left_wheel_visual">
        <geometry>
          <cylinder>
            <radius> .0625 </radius>
            <length> .025 </length>
          </cylinder>
        </geometry>
      </visual>
    </link>
    <link name="laser_front_right_wheel">
      <pose> 0.1365 -0.2364 0.0625 0 1.5707 -0.866025403784 </pose>
      <collision name="laser_front_right_wheel_collision">
        <geometry>
          <cylinder>
            <radius> .0625 </radius>
            <length> .025 </length>
          </cylinder>
        </geometry>
        <surface>
          <friction>
            <ode>
              <mu>0.3</mu>
              <mu2>0</mu2>
            </ode>
          </friction>
        </surface>
      </collision>
      <visual name="laser_front_right_wheel_visual">
        <geometry>
          <cylinder>
            <radius> .0625 </radius>
            <length> .025 </length>
          </cylinder>
        </geometry>
      </visual>
    </link>
    <joint name="mobile_base_back_wheel_joint" type="revolute">
      <child>laser_back_wheel</child>
      <parent>mobile_base_body</parent>
      <axis>
        <xyz>0 0 1</xyz>
        <limit>
          <!-- <lower>-17.4358</lower> -->
          <!-- <upper>17.4358</upper> -->
          <effort>100</effort>
          <velocity>50000</velocity>
        </limit>
        <dynamics>
          <damping>1</damping>
          <friction>0</friction>
          <spring_reference>0</spring_reference>
          <spring_stiffness>0</spring_stiffness>
        </dynamics>
        <use_parent_model_frame>0</use_parent_model_frame>
      </axis>
      <physics>
        <ode>
          <implicit_spring_damper>1</implicit_spring_damper>
          <cfm_damping>1</cfm_damping>
          <limit>
            <cfm>0</cfm>
            <erp>0.2</erp>
          </limit>
        </ode>
      </physics>
    </joint>
    <joint name="mobile_base_left_wheel_joint" type="revolute">
      <child>laser_front_left_wheel</child>
      <parent>mobile_base_body</parent>
      <axis>
        <xyz>0 0 1</xyz>
        <limit>
          <!-- <lower>-17.4358</lower> -->
          <!-- <upper>17.4358</upper> -->
          <effort>100</effort>
          <velocity>50000</velocity>
        </limit>
        <dynamics>
          <damping>1</damping>
          <friction>0</friction>
          <spring_reference>0</spring_reference>
          <spring_stiffness>0</spring_stiffness>
        </dynamics>
        <use_parent_model_frame>0</use_parent_model_frame>
      </axis>
      <physics>
        <ode>
          <implicit_spring_damper>1</implicit_spring_damper>
          <cfm_damping>1</cfm_damping>
          <limit>
            <cfm>0</cfm>
            <erp>0.2</erp>
          </limit>
        </ode>
      </physics>
    </joint>
    <joint name="mobile_base_right_wheel_joint" type="revolute">
      <child>laser_front_right_wheel</child>
      <parent>mobile_base_body</parent>
      <axis>
        <xyz> 0 0 -1</xyz>
        <limit>
          <!-- <lower>-17.4358</lower> -->
          <!-- <upper>17.4358</upper> -->
          <effort>100</effort>
          <velocity>50000</velocity>
        </limit>
        <dynamics>
          <damping>1</damping>
          <friction>0</friction>
          <spring_reference>0</spring_reference>
          <spring_stiffness>0</spring_stiffness>
        </dynamics>
        <use_parent_model_frame>0</use_parent_model_frame>
      </axis>
      <physics>
        <ode>
          <implicit_spring_damper>1</implicit_spring_damper>
          <cfm_damping>1</cfm_damping>
          <limit>
            <cfm>0</cfm>
            <erp>0.2</erp>
          </limit>
        </ode>
      </physics>
    </joint>
    <plugin name="controlboard_mobile_base" filename="libgazebo_yarp_controlboard.so">
      <yarpConfigurationFile>model://ikart_v1/conf/gazebo_ikart_mobile_base.ini</yarpConfigurationFile>
    </plugin>
  </model>
</sdf>
